<mujoco model="mb_xarm">
  <compiler angle="radian"/>
  <asset>
    <mesh name="link_base" file="link_base.STL"/>
    <mesh name="link1" file="link1.STL"/>
    <mesh name="link2" file="link2.STL"/>
    <mesh name="link3" file="link3.STL"/>
    <mesh name="link4" file="link4.STL"/>
    <mesh name="link5" file="link5.STL"/>
    <mesh name="link6" file="link6.STL"/>
    <mesh name="end_tool" file="end_tool.STL"/>
    <mesh name="RIQ_palm" file="RIQ_palm.stl" scale="0.001 0.001 0.001"/>
    <mesh name="RIQ_link_1" file="RIQ_link_1.stl" scale="0.001 0.001 0.001"/>
    <mesh name="RIQ_link_2" file="RIQ_link_2.stl" scale="0.001 0.001 0.001"/>
    <mesh name="RIQ_link_3" file="RIQ_link_3.stl" scale="0.001 0.001 0.001"/>
    <mesh name="RIQ_link_0" file="RIQ_link_0.stl" scale="0.001 0.001 0.001"/>
  </asset>
  <worldbody>
    <geom type="mesh" rgba="1 1 1 1" mesh="link_base"/>
    <geom pos="0 0.3 0" type="mesh" rgba="1 1 1 1" mesh="link_base"/>
    <body name="link1" pos="0 0 0.267">
      <inertial pos="-0.0042142 0.02821 -0.0087788" quat="0.917781 -0.277115 0.0606681 0.277858" mass="0.42603" diaginertia="0.00144551 0.00137757 0.000823511"/>
      <joint name="joint1" pos="0 0 0" axis="0 0 1" range="-6.28319 6.28319" actuatorfrcrange="-50 50" damping="10" frictionloss="1"/>
      <geom type="mesh" rgba="1 1 1 1" mesh="link1"/>
      <body name="link2" quat="0.707105 -0.707108 0 0">
        <inertial pos="-3.3178e-05 -0.12849 0.026337" quat="0.447793 0.894132 -0.00224061 0.00218314" mass="0.56095" diaginertia="0.00319151 0.00311598 0.000980804"/>
        <joint name="joint2" pos="0 0 0" axis="0 0 1" range="-2.059 2.0944" actuatorfrcrange="-50 50" damping="10" frictionloss="1"/>
        <geom type="mesh" rgba="1 1 1 1" mesh="link2"/>
        <body name="link3" pos="0 -0.293 0" quat="0.707105 0.707108 0 0">
          <inertial pos="0.04223 -0.023258 -0.0096674" quat="0.883205 0.339803 0.323238 0.000542237" mass="0.44463" diaginertia="0.00133227 0.00119126 0.000780475"/>
          <joint name="joint3" pos="0 0 0" axis="0 0 1" range="-6.28319 6.28319" actuatorfrcrange="-30 30" damping="5" frictionloss="1"/>
          <geom type="mesh" rgba="1 1 1 1" mesh="link3"/>
          <body name="link4" pos="0.0525 0 0" quat="0.707105 0.707108 0 0">
            <inertial pos="0.067148 -0.10732 0.024479" quat="0.0654142 0.483317 -0.738663 0.465298" mass="0.52387" diaginertia="0.00288984 0.00282705 0.000894409"/>
            <joint name="joint4" pos="0 0 0" axis="0 0 1" range="-0.19198 3.927" actuatorfrcrange="-30 30" damping="5" frictionloss="1"/>
            <geom type="mesh" rgba="1 1 1 1" mesh="link4"/>
            <body name="link5" pos="0.0775 -0.3425 0" quat="0.707105 0.707108 0 0">
              <inertial pos="-0.00023397 0.036705 -0.080064" quat="0.981064 -0.19003 0.00637998 0.0369004" mass="0.18554" diaginertia="0.00099553 0.000988613 0.000247126"/>
              <joint name="joint5" pos="0 0 0" axis="0 0 1" range="-6.28319 6.28319" actuatorfrcrange="-30 30" damping="5" frictionloss="1"/>
              <geom type="mesh" rgba="1 1 1 1" mesh="link5"/>
              <body name="link6" quat="0.707105 0.707108 0 0">
                <inertial pos="0.058911 0.028469 0.0068428" quat="-0.188705 0.793535 0.166088 0.554173" mass="0.31344" diaginertia="0.000827892 0.000768871 0.000386708"/>
                <joint name="joint6" pos="0 0 0" axis="0 0 1" range="-1.69297 3.14159" actuatorfrcrange="-20 20" damping="2" frictionloss="1"/>
                <geom type="mesh" rgba="1 1 1 1" mesh="link6"/>
                <body name="link7" pos="0.076 0.097 0" quat="0.707105 -0.707108 0 0">
                  <inertial pos="7.39297e-05 -0.00436054 -0.0119241" quat="0.493145 0.50459 -0.507093 0.495028" mass="0.33468" diaginertia="0.000263129 0.000175352 0.000124214"/>
                  <joint name="joint7" pos="0 0 0" axis="0 0 1" range="-6.28319 6.28319" actuatorfrcrange="-20 20" damping="2" frictionloss="1"/>
                  <geom type="mesh" rgba="0.753 0.753 0.753 1" mesh="end_tool"/>
                  <geom pos="0.00148646 2.68671e-07 0.00036187" quat="0.707105 0.707108 0 0" type="mesh" mesh="RIQ_palm"/>
                  <body name="RIQ_link_1_joint_a" pos="0.044475 -1.51916e-07 0.041358" quat="0.499999 0.500001 -0.500001 0.499999">
                    <joint name="RIQ_palm_RIQ_link_1_joint_a" pos="0 0 0" axis="0 0 1" range="-0.0940732 1.12766" actuatorfrcrange="-2.5 2.5"/>
                    <geom pos="0.017606 -0.0215932 0" quat="0.966801 0 0 -0.25553" type="mesh" mesh="RIQ_link_1"/>
                    <body name="RIQ_link_2_joint_a" pos="0.0496867 -0.0282374 0" quat="0.966801 0 0 -0.25553">
                      <joint name="RIQ_link_1_RIQ_link_2_joint_a" pos="0 0 0" axis="0 0 1" range="0 1.5708" actuatorfrcrange="-2.5 2.5"/>
                      <geom pos="0.0137009 -0.00787653 -0.00949288" type="mesh" mesh="RIQ_link_2"/>
                      <body name="RIQ_link_3_joint_a" pos="0.03894 0 0">
                        <joint name="RIQ_link_2_RIQ_link_3_joint_a" pos="0 0 0" axis="0 0 1" range="-0.953124 0.757298" actuatorfrcrange="-2.5 2.5"/>
                        <geom pos="0.00837663 0.00297712 -5.599e-05" quat="0.966801 0 0 0.25553" type="mesh" rgba="1 0 0 0" mesh="RIQ_link_3"/>
                      </body>
                    </body>
                  </body>
                  <body name="RIQ_link_0_joint_b" pos="-0.040507 -0.0365131 0.0198439" quat="0.499999 0.500001 0.499999 0.500001">
                    <joint name="RIQ_palm_RIQ_link_0_joint_b" pos="0 0 0" axis="0 0 1" range="-0.296706 0.296706" actuatorfrcrange="-2.5 2.5"/>
                    <geom pos="-7.0118e-11 0.021877 -0.00397" quat="0.5 0.5 0.5 0.5" type="mesh" mesh="RIQ_link_0"/>
                    <body name="RIQ_link_1_joint_b" pos="-7.0118e-11 0.021877 -0.00397" quat="0.5 0.5 0.5 0.5">
                      <joint name="RIQ_link_0_RIQ_link_1_joint_b" pos="0 0 0" axis="0 0 1" range="-0.0940732 1.12766" actuatorfrcrange="-2.5 2.5"/>
                      <geom pos="0.0496867 -0.0282374 0" quat="0.966801 0 0 -0.25553" type="mesh" mesh="RIQ_link_1"/>
                      <body name="RIQ_link_2_joint_b" pos="0.0496867 -0.0282374 0" quat="0.966801 0 0 -0.25553">
                        <joint name="RIQ_link_1_RIQ_link_2_joint_b" pos="0 0 0" axis="0 0 1" range="0 1.5708" actuatorfrcrange="-2.5 2.5"/>
                        <geom pos="0.03894 0 0" type="mesh" mesh="RIQ_link_2"/>
                        <body name="RIQ_link_3_joint_b" pos="0.03894 0 0">
                          <joint name="RIQ_link_2_RIQ_link_3_joint_b" pos="0 0 0" axis="0 0 1" range="-0.953124 0.757298" actuatorfrcrange="-2.5 2.5"/>
                          <geom pos="0.00837663 0.00297712 -5.599e-05" quat="0.966801 0 0 0.25553" type="mesh" rgba="0 1 0 0" mesh="RIQ_link_3"/>
                        </body>
                      </body>
                    </body>
                  </body>
                  <body name="RIQ_link_0_joint_c" pos="-0.040507 0.0365129 0.0198441" quat="0.499999 0.500001 0.499999 0.500001">
                    <joint name="RIQ_palm_RIQ_link_0_joint" pos="0 0 0" axis="0 0 1" range="-0.296706 0.296706" actuatorfrcrange="-2.5 2.5"/>
                    <geom pos="-7.0118e-11 0.021877 -0.00397" quat="0.5 0.5 0.5 0.5" type="mesh" mesh="RIQ_link_0"/>
                    <body name="RIQ_link_1_joint_c" pos="-7.0118e-11 0.021877 -0.00397" quat="0.5 0.5 0.5 0.5">
                      <joint name="RIQ_link_0_RIQ_link_1_joint_c" pos="0 0 0" axis="0 0 1" range="-0.0940732 1.12766" actuatorfrcrange="-2.5 2.5"/>
                      <geom pos="0.0496867 -0.0282374 0" quat="0.966801 0 0 -0.25553" type="mesh" mesh="RIQ_link_1"/>
                      <body name="RIQ_link_2_joint_c" pos="0.0496867 -0.0282374 0" quat="0.966801 0 0 -0.25553">
                        <joint name="RIQ_link_1_RIQ_link_2_joint_c" pos="0 0 0" axis="0 0 1" range="0 1.5708" actuatorfrcrange="-2.5 2.5"/>
                        <geom pos="0.03894 0 0" type="mesh" mesh="RIQ_link_2"/>
                        <body name="RIQ_link_3_joint_c" pos="0.03894 0 0">
                          <joint name="RIQ_link_2_RIQ_link_3_joint_c" pos="0 0 0" axis="0 0 1" range="-0.953124 0.757298" actuatorfrcrange="-2.5 2.5"/>
                          <geom pos="0.00837663 0.00297712 -5.599e-05" quat="0.966801 0 0 0.25553" type="mesh" rgba="0 0 1 0" mesh="RIQ_link_3"/>
                        </body>
                      </body>
                    </body>
                  </body>
                </body>
              </body>
            </body>
          </body>
        </body>
      </body>
    </body>
    <body name="link1_right" pos="0 0.3 0.267">
      <inertial pos="-0.0042142 0.02821 -0.0087788" quat="0.917781 -0.277115 0.0606681 0.277858" mass="0.42603" diaginertia="0.00144551 0.00137757 0.000823511"/>
      <joint name="joint1_right" pos="0 0 0" axis="0 0 1" range="-6.28319 6.28319" actuatorfrcrange="-50 50" damping="10" frictionloss="1"/>
      <geom type="mesh" rgba="1 1 1 1" mesh="link1"/>
      <body name="link2_right" quat="0.707105 -0.707108 0 0">
        <inertial pos="-3.3178e-05 -0.12849 0.026337" quat="0.447793 0.894132 -0.00224061 0.00218314" mass="0.56095" diaginertia="0.00319151 0.00311598 0.000980804"/>
        <joint name="joint2_right" pos="0 0 0" axis="0 0 1" range="-2.059 2.0944" actuatorfrcrange="-50 50" damping="10" frictionloss="1"/>
        <geom type="mesh" rgba="1 1 1 1" mesh="link2"/>
        <body name="link3_right" pos="0 -0.293 0" quat="0.707105 0.707108 0 0">
          <inertial pos="0.04223 -0.023258 -0.0096674" quat="0.883205 0.339803 0.323238 0.000542237" mass="0.44463" diaginertia="0.00133227 0.00119126 0.000780475"/>
          <joint name="joint3_right" pos="0 0 0" axis="0 0 1" range="-6.28319 6.28319" actuatorfrcrange="-30 30" damping="5" frictionloss="1"/>
          <geom type="mesh" rgba="1 1 1 1" mesh="link3"/>
          <body name="link4_right" pos="0.0525 0 0" quat="0.707105 0.707108 0 0">
            <inertial pos="0.067148 -0.10732 0.024479" quat="0.0654142 0.483317 -0.738663 0.465298" mass="0.52387" diaginertia="0.00288984 0.00282705 0.000894409"/>
            <joint name="joint4_right" pos="0 0 0" axis="0 0 1" range="-0.19198 3.927" actuatorfrcrange="-30 30" damping="5" frictionloss="1"/>
            <geom type="mesh" rgba="1 1 1 1" mesh="link4"/>
            <body name="link5_right" pos="0.0775 -0.3425 0" quat="0.707105 0.707108 0 0">
              <inertial pos="-0.00023397 0.036705 -0.080064" quat="0.981064 -0.19003 0.00637998 0.0369004" mass="0.18554" diaginertia="0.00099553 0.000988613 0.000247126"/>
              <joint name="joint5_right" pos="0 0 0" axis="0 0 1" range="-6.28319 6.28319" actuatorfrcrange="-30 30" damping="5" frictionloss="1"/>
              <geom type="mesh" rgba="1 1 1 1" mesh="link5"/>
              <body name="link6_right" quat="0.707105 0.707108 0 0">
                <inertial pos="0.058911 0.028469 0.0068428" quat="-0.188705 0.793535 0.166088 0.554173" mass="0.31344" diaginertia="0.000827892 0.000768871 0.000386708"/>
                <joint name="joint6_right" pos="0 0 0" axis="0 0 1" range="-1.69297 3.14159" actuatorfrcrange="-20 20" damping="2" frictionloss="1"/>
                <geom type="mesh" rgba="1 1 1 1" mesh="link6"/>
                <body name="link7_right" pos="0.076 0.097 0" quat="0.707105 -0.707108 0 0">
                  <inertial pos="7.39297e-05 -0.00436054 -0.0119241" quat="0.493145 0.50459 -0.507093 0.495028" mass="0.33468" diaginertia="0.000263129 0.000175352 0.000124214"/>
                  <joint name="joint7_right" pos="0 0 0" axis="0 0 1" range="-6.28319 6.28319" actuatorfrcrange="-20 20" damping="2" frictionloss="1"/>
                  <geom type="mesh" rgba="0.753 0.753 0.753 1" mesh="end_tool"/>
                  <geom pos="0.00148646 2.68671e-07 0.00036187" quat="0.707105 0.707108 0 0" type="mesh" mesh="RIQ_palm"/>
                  <body name="RIQ_link_1_joint_a_right" pos="0.044475 -1.51916e-07 0.041358" quat="0.499999 0.500001 -0.500001 0.499999">
                    <joint name="RIQ_palm_RIQ_link_1_joint_a_right" pos="0 0 0" axis="0 0 1" range="-0.0940732 1.12766" actuatorfrcrange="-2.5 2.5"/>
                    <geom pos="0.017606 -0.0215932 0" quat="0.966801 0 0 -0.25553" type="mesh" mesh="RIQ_link_1"/>
                    <body name="RIQ_link_2_joint_a_right" pos="0.0496867 -0.0282374 0" quat="0.966801 0 0 -0.25553">
                      <joint name="RIQ_link_1_RIQ_link_2_joint_a_right" pos="0 0 0" axis="0 0 1" range="0 1.5708" actuatorfrcrange="-2.5 2.5"/>
                      <geom pos="0.0137009 -0.00787653 -0.00949288" type="mesh" mesh="RIQ_link_2"/>
                      <body name="RIQ_link_3_joint_a_right" pos="0.03894 0 0">
                        <joint name="RIQ_link_2_RIQ_link_3_joint_a_right" pos="0 0 0" axis="0 0 1" range="-0.953124 0.757298" actuatorfrcrange="-2.5 2.5"/>
                        <geom pos="0.00837663 0.00297712 -5.599e-05" quat="0.966801 0 0 0.25553" type="mesh" rgba="1 0 0 0" mesh="RIQ_link_3"/>
                      </body>
                    </body>
                  </body>
                  <body name="RIQ_link_0_joint_b_right" pos="-0.040507 -0.0365131 0.0198439" quat="0.499999 0.500001 0.499999 0.500001">
                    <joint name="RIQ_palm_RIQ_link_0_joint_b_right" pos="0 0 0" axis="0 0 1" range="-0.296706 0.296706" actuatorfrcrange="-2.5 2.5"/>
                    <geom pos="-7.0118e-11 0.021877 -0.00397" quat="0.5 0.5 0.5 0.5" type="mesh" mesh="RIQ_link_0"/>
                    <body name="RIQ_link_1_joint_b_right" pos="-7.0118e-11 0.021877 -0.00397" quat="0.5 0.5 0.5 0.5">
                      <joint name="RIQ_link_0_RIQ_link_1_joint_b_right" pos="0 0 0" axis="0 0 1" range="-0.0940732 1.12766" actuatorfrcrange="-2.5 2.5"/>
                      <geom pos="0.0496867 -0.0282374 0" quat="0.966801 0 0 -0.25553" type="mesh" mesh="RIQ_link_1"/>
                      <body name="RIQ_link_2_joint_b_right" pos="0.0496867 -0.0282374 0" quat="0.966801 0 0 -0.25553">
                        <joint name="RIQ_link_1_RIQ_link_2_joint_b_right" pos="0 0 0" axis="0 0 1" range="0 1.5708" actuatorfrcrange="-2.5 2.5"/>
                        <geom pos="0.03894 0 0" type="mesh" mesh="RIQ_link_2"/>
                        <body name="RIQ_link_3_joint_b_right" pos="0.03894 0 0">
                          <joint name="RIQ_link_2_RIQ_link_3_joint_b_right" pos="0 0 0" axis="0 0 1" range="-0.953124 0.757298" actuatorfrcrange="-2.5 2.5"/>
                          <geom pos="0.00837663 0.00297712 -5.599e-05" quat="0.966801 0 0 0.25553" type="mesh" rgba="0 1 0 0" mesh="RIQ_link_3"/>
                        </body>
                      </body>
                    </body>
                  </body>
                  <body name="RIQ_link_0_joint_c_right" pos="-0.040507 0.0365129 0.0198441" quat="0.499999 0.500001 0.499999 0.500001">
                    <joint name="RIQ_palm_RIQ_link_0_joint_right" pos="0 0 0" axis="0 0 1" range="-0.296706 0.296706" actuatorfrcrange="-2.5 2.5"/>
                    <geom pos="-7.0118e-11 0.021877 -0.00397" quat="0.5 0.5 0.5 0.5" type="mesh" mesh="RIQ_link_0"/>
                    <body name="RIQ_link_1_joint_c_right" pos="-7.0118e-11 0.021877 -0.00397" quat="0.5 0.5 0.5 0.5">
                      <joint name="RIQ_link_0_RIQ_link_1_joint_c_right" pos="0 0 0" axis="0 0 1" range="-0.0940732 1.12766" actuatorfrcrange="-2.5 2.5"/>
                      <geom pos="0.0496867 -0.0282374 0" quat="0.966801 0 0 -0.25553" type="mesh" mesh="RIQ_link_1"/>
                      <body name="RIQ_link_2_joint_c_right" pos="0.0496867 -0.0282374 0" quat="0.966801 0 0 -0.25553">
                        <joint name="RIQ_link_1_RIQ_link_2_joint_c_right" pos="0 0 0" axis="0 0 1" range="0 1.5708" actuatorfrcrange="-2.5 2.5"/>
                        <geom pos="0.03894 0 0" type="mesh" mesh="RIQ_link_2"/>
                        <body name="RIQ_link_3_joint_c_right" pos="0.03894 0 0">
                          <joint name="RIQ_link_2_RIQ_link_3_joint_c_right" pos="0 0 0" axis="0 0 1" range="-0.953124 0.757298" actuatorfrcrange="-2.5 2.5"/>
                          <geom pos="0.00837663 0.00297712 -5.599e-05" quat="0.966801 0 0 0.25553" type="mesh" rgba="0 0 1 0" mesh="RIQ_link_3"/>
                        </body>
                      </body>
                    </body>
                  </body>
                </body>
              </body>
            </body>
          </body>
        </body>
      </body>
    </body>
  </worldbody>
</mujoco>
